Workbook
Name Slicer_Case_Status: #N/A
Name Slicer_Crime_month_name: #N/A
Name Slicer_Crime_Type: #N/A
Name Slicer_Crime_Type1: #N/A
Name Slicer_Crime_Type2: #N/A
Name Slicer_Crime_Type3: #N/A
Name Slicer_Crime_Type4: #N/A
Name Slicer_Crime_Type5: #N/A
Name Slicer_Crime_Year1: #N/A
Name Slicer_District: #N/A
Name Slicer_District1: #N/A
Name Slicer_Severity_Level: #N/A
Name Slicer_Victim_Gender: #N/A
Name Slicer_Victim_Gender1: #N/A

Sheet raw_data
A1: Crime_ID | B1: Crime_Date | C1: Crime_Type | D1: District | E1: Victim_Gender | F1: Case_Status | G1: Severity_Level
A2: CRM00054 | B2: 45849 | C2: Theft | D2: Karan | E2: Male | F2: Closed
A3: CRM00290 | B3: 45714 | C3: Burglary | E3: Male | F3: Closed | G3: Medium
A4: CRM00143 | B4: 46168 | C4: Theft | D4: Wadajir | E4: Female | G4: Medium
A5: CRM00198 | B5: 45705 | C5: Assault | D5: Wadajir | E5: Male | F5: Open | G5: High
A6: CRM00244 | B6: 46080 | C6: Assault | D6: Hodan | E6: Female | F6: Under Investigation | G6: High
A7: CRM00265 | B7: 45705 | C7: Fraud | D7: Wadajir | E7: Male | F7: Under Investigation | G7: Medium
A8: CRM00138 | B8: 46098 | C8: Theft | D8: Yaqshid | E8: Female | F8: Under Investigation | G8: Medium
A9: CRM00028 | B9: 45702 | C9: Fraud | D9: Yaqshid | E9: Male | G9: Medium
A10: CRM00018 | B10: 45816 | C10: Robbery | D10: Yaqshid | E10: Male | F10: Under Investigation | G10: High
A11: CRM00096 | B11: 45755 | C11: Fraud | D11: Daynile | E11: Male | F11: Under Investigation | G11: Medium
A12: CRM00153 | B12: 46118 | C12: Theft | D12: Hodan | E12: Unknown | F12: Under Investigation | G12: Medium
B13: 46215 | C13: Assault | D13: Waberi | E13: Male | F13: Open | G13: High
A14: CRM00122 | B14: 46003 | C14: Theft | D14: Hodan | E14: Female | F14: Under Investigation | G14: Medium
A15: CRM00245 | B15: 46178 | C15: Theft | D15: Daynile | E15: Male | F15: Open | G15: Medium
A16: CRM00035 | B16: 45817 | C16: Traffic Offense | D16: Karan | E16: Male | F16: Under Investigation | G16: Low
A17: CRM00210 | B17: 45755 | D17: Daynile | E17: Female | F17: Closed | G17: High
A18: CRM00073 | B18: 45974 | C18: Traffic Offense | D18: Yaqshid | E18: Female | F18: Under Investigation | G18: Low
A19: CRM00262 | B19: 46042 | C19: Assault | D19: Wadajir | E19: Female | F19: Closed
A20: CRM00235 | B20: 45712 | C20: Theft | E20: Male | F20: Referred | G20: Medium
A21: CRM00158 | B21: 45919 | C21: Assault | D21: Wadajir | E21: Male | F21: Under Investigation | G21: High
A22: CRM00251 | B22: 46068 | C22: Robbery | D22: Hodan | E22: Female | F22: Closed | G22: High
A23: CRM00213 | B23: - | C23: Assault | D23: Wadajir | E23: Male | F23: Open | G23: High
A24: CRM00026 | B24: 45782 | C24: Theft | D24: Hodan | E24: Male | G24: Medium
A25: CRM00216 | B25: 46167 | D25: Karan | E25: Male | F25: Closed | G25: High
A26: CRM00064 | B26: 45885 | D26: Karan | E26: Male | F26: Open | G26: Medium
A27: CRM00278 | B27: N/A | C27: Robbery | D27: Daynile | E27: Male | F27: Closed | G27: High
A28: CRM00021 | B28: 45971 | C28: Traffic Offense | D28: Daynile | E28: Male | F28: Closed | G28: Low
A29: CRM00045 | B29: 45922 | C29: Robbery | D29: Hodan | E29: Male | F29: Closed | G29: High
A30: CRM00252 | B30: 46136 | C30: Assault | D30: Hodan | E30: Unknown | F30: Closed | G30: High
A31: CRM00234 | C31: Traffic Offense | D31: Daynile | E31: Unknown | F31: Closed | G31: Low
A32: CRM00049 | B32: 46208 | C32: Burglary | D32: Yaqshid | E32: Unknown | F32: Under Investigation | G32: Medium
A33: CRM00178 | B33: 46182 | C33: Theft | D33: Daynile | E33: NULL | F33: Under Investigation | G33: Medium
A34: CRM00140 | B34: 45671 | C34: Robbery | D34: Wadajir | E34: Female | F34: Under Investigation | G34: High
A35: CRM00215 | B35: 45853 | C35: Fraud | D35: Daynile | E35: Female | F35: Under Investigation | G35: Medium
A36: CRM00286 | B36: 45680 | C36: Fraud | D36: Wadajir | F36: Closed | G36: Medium
A37: CRM00240 | B37: 45761 | C37: Traffic Offense | D37: Waberi | E37: Male | F37: Open | G37: Low
B38: 45822 | C38: Robbery | D38: Hodan | E38: Unknown | F38: Closed | G38: High
A39: CRM00161 | B39: 45957 | C39: Theft | D39: Karan | E39: Male | F39: Under Investigation
A40: CRM00254 | B40: N/A | D40: Karan | E40: Male | F40: Open | G40: High
...

Sheet pivottable
A3: Row Labels | B3: Count of Crime_ID
A4: Assault | B4: 60
A5: Burglary | B5: 18 | H5: Row Labels | I5: Count of Crime_ID
A6: Fraud | B6: 57 | H6: Daynile | I6: 38
A7: Robbery | B7: 44 | H7: Hodan | I7: 84
A8: Theft | B8: 85 | H8: Karan | I8: 32
A9: Traffic Offense | B9: 28 | H9: Waberi | I9: 32
A10: Grand Total | B10: 292 | H10: Wadajir | I10: 62
H11: Yaqshid | I11: 44
H12: Grand Total | I12: 292
A17: Row Labels | B17: Count of Crime_ID | F17: Row Labels | G17: Count of Crime_ID
A18: Female | B18: 89 | F18: Closed | G18: 123
A19: Male | B19: 160 | F19: Open | G19: 67
A20: Unknown | B20: 43 | F20: Referred | G20: 25
A21: Grand Total | B21: 292 | F21: Under Investigation | G21: 77
F22: Grand Total | G22: 292
A29: Row Labels | B29: Count of Crime_ID | G29: Row Labels | H29: Count of Crime_month name
A30: High | B30: 106 | G30: January | H30: 27
A31: Low | B31: 30 | G31: February | H31: 34
A32: Medium | B32: 156 | G32: March | H32: 21
A33: Grand Total | B33: 292 | G33: April | H33: 28
G34: May | H34: 30
G35: June | H35: 24
G36: July | H36: 56
G37: August | H37: 16
G38: September | H38: 17
A39: Row Labels | B39: Count of Crime_Year | G39: October | H39: 13
A40: 2025 | B40: 169 | G40: November | H40: 13
A41: 2026 | B41: 123 | G41: December | H41: 13
B42: 1 | H42: 1
A43: Grand Total | B43: 293 | G43: Grand Total | H43: 293
C53: Count of Crime_Year | D53: Column Labels
C54: Row Labels | D54: 2025 | E54: 2026 | G54: Grand Total
C55: Assault | D55: 33 | E55: 27 | G55: 60
C56: Burglary | D56: 15 | E56: 3 | G56: 18
C57: Fraud | D57: 33 | E57: 24 | G57: 57
C58: Robbery | D58: 25 | E58: 19 | G58: 44
C59: Theft | D59: 46 | E59: 39 | G59: 85
C60: Traffic Offense | D60: 17 | E60: 11 | F60: 1 | G60: 29
C61: Grand Total | D61: 169 | E61: 123 | F61: 1 | G61: 293

Sheet clean_data
A1: Crime_ID | B1: Crime_Date | C1: Crime_Type | D1: District | E1: Victim_Gender | F1: Case_Status | G1: Severity_Level | H1: Crime_Year | I1: Crime_month | J1: Crime_month name | K1: Data_Quality_Flag | L1: Duplicate_Flag | M1: Record_Status | N1: concat
A2: CRM001 | B2: 46215 | C2: Assault | D2: Waberi | E2: Male | F2: Open | G2: High | H2: =IF(B2="","",YEAR(B2)) -> 2026 | I2: =IF(B2="","",MONTH(B2)) -> 7 | J2: =IF(B2="","",TEXT(B2,"mmmm")) -> July | K2: =IF(COUNTBLANK(A2:G2)+COUNTIF(A2:G2,"Unknown")+COUNTIF(A2:G2,"-")>0,"Needs Review","OK") -> OK | L2: =IF(COUNTIF(A$2:A2,A2)>1,"Duplicate","Unique") -> Unique | M2: =IF(OR(K2="Needs Review",L2="Duplicate"),"Review","Ready") -> Ready | N2: =clean_data!D13 & " - " & clean_data!C13 -> Hodan - Traffic Offense
A3: CRM002 | B3: 45822 | C3: Robbery | D3: Hodan | E3: Unknown | F3: Closed | G3: High | H3: =IF(B3="","",YEAR(B3)) -> 2025 | I3: =IF(B3="","",MONTH(B3)) -> 6 | J3: =IF(B3="","",TEXT(B3,"mmmm")) -> June | K3: =IF(COUNTBLANK(A3:G3)+COUNTIF(A3:G3,"Unknown")+COUNTIF(A3:G3,"-")>0,"Needs Review","OK") -> Needs Review | L3: =IF(COUNTIF(A$2:A3,A3)>1,"Duplicate","Unique") -> Unique | M3: =IF(OR(K3="Needs Review",L3="Duplicate"),"Review","Ready") -> Review | N3: =clean_data!D38 & " - " & clean_data!C38 -> Karan - Assault
A4: CRM003 | B4: 46017 | C4: Robbery | D4: Daynile | E4: Male | F4: Open | G4: High | H4: =IF(B4="","",YEAR(B4)) -> 2025 | I4: =IF(B4="","",MONTH(B4)) -> 12 | J4: =IF(B4="","",TEXT(B4,"mmmm")) -> December | K4: =IF(COUNTBLANK(A4:G4)+COUNTIF(A4:G4,"Unknown")+COUNTIF(A4:G4,"-")>0,"Needs Review","OK") -> OK | L4: =IF(COUNTIF(A$2:A4,A4)>1,"Duplicate","Unique") -> Unique | M4: =IF(OR(K4="Needs Review",L4="Duplicate"),"Review","Ready") -> Ready | N4: =clean_data!D46 & " - " & clean_data!C46 -> Hodan - Burglary
A5: CRM004 | B5: 45832 | C5: Assault | D5: Yaqshid | E5: Female | F5: Referred | G5: High | H5: =IF(B5="","",YEAR(B5)) -> 2025 | I5: =IF(B5="","",MONTH(B5)) -> 6 | J5: =IF(B5="","",TEXT(B5,"mmmm")) -> June | K5: =IF(COUNTBLANK(A5:G5)+COUNTIF(A5:G5,"Unknown")+COUNTIF(A5:G5,"-")>0,"Needs Review","OK") -> OK | L5: =IF(COUNTIF(A$2:A5,A5)>1,"Duplicate","Unique") -> Unique | M5: =IF(OR(K5="Needs Review",L5="Duplicate"),"Review","Ready") -> Ready | N5: =clean_data!D73 & " - " & clean_data!C73 -> Hodan - Fraud
A6: CRM005 | B6: 46045 | C6: Assault | D6: Daynile | E6: Male | F6: Under Investigation | G6: High | H6: =IF(B6="","",YEAR(B6)) -> 2026 | I6: =IF(B6="","",MONTH(B6)) -> 1 | J6: =IF(B6="","",TEXT(B6,"mmmm")) -> January | K6: =IF(COUNTBLANK(A6:G6)+COUNTIF(A6:G6,"Unknown")+COUNTIF(A6:G6,"-")>0,"Needs Review","OK") -> OK | L6: =IF(COUNTIF(A$2:A6,A6)>1,"Duplicate","Unique") -> Unique | M6: =IF(OR(K6="Needs Review",L6="Duplicate"),"Review","Ready") -> Ready | N6: =clean_data!D111 & " - " & clean_data!C111 -> Wadajir - Assault
A7: CRM006 | B7: 46039 | C7: Robbery | D7: Daynile | E7: Male | F7: Closed | G7: High | H7: =IF(B7="","",YEAR(B7)) -> 2026 | I7: =IF(B7="","",MONTH(B7)) -> 1 | J7: =IF(B7="","",TEXT(B7,"mmmm")) -> January | K7: =IF(COUNTBLANK(A7:G7)+COUNTIF(A7:G7,"Unknown")+COUNTIF(A7:G7,"-")>0,"Needs Review","OK") -> OK | L7: =IF(COUNTIF(A$2:A7,A7)>1,"Duplicate","Unique") -> Unique | M7: =IF(OR(K7="Needs Review",L7="Duplicate"),"Review","Ready") -> Ready | N7: =clean_data!D118 & " - " & clean_data!C118 -> Hodan - Assault
A8: CRM007 | B8: 46159 | C8: Theft | D8: Wadajir | E8: Male | F8: Under Investigation | G8: Medium | H8: =IF(B8="","",YEAR(B8)) -> 2026 | I8: =IF(B8="","",MONTH(B8)) -> 5 | J8: =IF(B8="","",TEXT(B8,"mmmm")) -> May | K8: =IF(COUNTBLANK(A8:G8)+COUNTIF(A8:G8,"Unknown")+COUNTIF(A8:G8,"-")>0,"Needs Review","OK") -> OK | L8: =IF(COUNTIF(A$2:A8,A8)>1,"Duplicate","Unique") -> Unique | M8: =IF(OR(K8="Needs Review",L8="Duplicate"),"Review","Ready") -> Ready | N8: =clean_data!D127 & " - " & clean_data!C127 -> Yaqshid - Theft
A9: CRM008 | B9: 45850 | C9: Traffic Offense | D9: Daynile | E9: Female | F9: Closed | G9: Low | H9: =IF(B9="","",YEAR(B9)) -> 2025 | I9: =IF(B9="","",MONTH(B9)) -> 7 | J9: =IF(B9="","",TEXT(B9,"mmmm")) -> July | K9: =IF(COUNTBLANK(A9:G9)+COUNTIF(A9:G9,"Unknown")+COUNTIF(A9:G9,"-")>0,"Needs Review","OK") -> OK | L9: =IF(COUNTIF(A$2:A9,A9)>1,"Duplicate","Unique") -> Unique | M9: =IF(OR(K9="Needs Review",L9="Duplicate"),"Review","Ready") -> Ready | N9: =clean_data!D133 & " - " & clean_data!C133 -> Yaqshid - Fraud
A10: CRM009 | B10: 46204 | C10: Theft | D10: Wadajir | E10: Male | F10: Open | G10: Medium | H10: =IF(B10="","",YEAR(B10)) -> 2026 | I10: =IF(B10="","",MONTH(B10)) -> 7 | J10: =IF(B10="","",TEXT(B10,"mmmm")) -> July | K10: =IF(COUNTBLANK(A10:G10)+COUNTIF(A10:G10,"Unknown")+COUNTIF(A10:G10,"-")>0,"Needs Review","OK") -> OK | L10: =IF(COUNTIF(A$2:A10,A10)>1,"Duplicate","Unique") -> Unique | M10: =IF(OR(K10="Needs Review",L10="Duplicate"),"Review","Ready") -> Ready | N10: =clean_data!D195 & " - " & clean_data!C195 -> Waberi - Robbery
A11: CRM010 | B11: 46063 | C11: Robbery | D11: Daynile | E11: Female | F11: Under Investigation | G11: High | H11: =IF(B11="","",YEAR(B11)) -> 2026 | I11: =IF(B11="","",MONTH(B11)) -> 2 | J11: =IF(B11="","",TEXT(B11,"mmmm")) -> February | K11: =IF(COUNTBLANK(A11:G11)+COUNTIF(A11:G11,"Unknown")+COUNTIF(A11:G11,"-")>0,"Needs Review","OK") -> OK | L11: =IF(COUNTIF(A$2:A11,A11)>1,"Duplicate","Unique") -> Unique | M11: =IF(OR(K11="Needs Review",L11="Duplicate"),"Review","Ready") -> Ready | N11: =clean_data!D215 & " - " & clean_data!C215 -> Hodan - Theft
A12: CRM011 | B12: 45748 | C12: Burglary | D12: Waberi | E12: Female | F12: Under Investigation | G12: Medium | H12: =IF(B12="","",YEAR(B12)) -> 2025 | I12: =IF(B12="","",MONTH(B12)) -> 4 | J12: =IF(B12="","",TEXT(B12,"mmmm")) -> April | K12: =IF(COUNTBLANK(A12:G12)+COUNTIF(A12:G12,"Unknown")+COUNTIF(A12:G12,"-")>0,"Needs Review","OK") -> OK | L12: =IF(COUNTIF(A$2:A12,A12)>1,"Duplicate","Unique") -> Unique | M12: =IF(OR(K12="Needs Review",L12="Duplicate"),"Review","Ready") -> Ready | N12: =clean_data!D226 & " - " & clean_data!C226 -> Daynile - Traffic Offense
A13: CRM012 | B13: 46161 | C13: Traffic Offense | D13: Hodan | E13: Female | F13: Open | G13: Low | H13: =IF(B13="","",YEAR(B13)) -> 2026 | I13: =IF(B13="","",MONTH(B13)) -> 5 | J13: =IF(B13="","",TEXT(B13,"mmmm")) -> May | K13: =IF(COUNTBLANK(A13:G13)+COUNTIF(A13:G13,"Unknown")+COUNTIF(A13:G13,"-")>0,"Needs Review","OK") -> OK | L13: =IF(COUNTIF(A$2:A13,A13)>1,"Duplicate","Unique") -> Unique | M13: =IF(OR(K13="Needs Review",L13="Duplicate"),"Review","Ready") -> Ready | N13: =clean_data!D242 & " - " & clean_data!C242 -> Waberi - Robbery
A14: CRM013 | B14: 46050 | C14: Theft | D14: Wadajir | E14: Male | F14: Closed | G14: Medium | H14: =IF(B14="","",YEAR(B14)) -> 2026 | I14: =IF(B14="","",MONTH(B14)) -> 1 | J14: =IF(B14="","",TEXT(B14,"mmmm")) -> January | K14: =IF(COUNTBLANK(A14:G14)+COUNTIF(A14:G14,"Unknown")+COUNTIF(A14:G14,"-")>0,"Needs Review","OK") -> OK | L14: =IF(COUNTIF(A$2:A14,A14)>1,"Duplicate","Unique") -> Unique | M14: =IF(OR(K14="Needs Review",L14="Duplicate"),"Review","Ready") -> Ready | N14: =clean_data!D267 & " - " & clean_data!C267 -> Hodan - Assault
A15: CRM014 | B15: 45951 | C15: Fraud | D15: Karan | E15: Male | F15: Open | G15: Medium | H15: =IF(B15="","",YEAR(B15)) -> 2025 | I15: =IF(B15="","",MONTH(B15)) -> 10 | J15: =IF(B15="","",TEXT(B15,"mmmm")) -> October | K15: =IF(COUNTBLANK(A15:G15)+COUNTIF(A15:G15,"Unknown")+COUNTIF(A15:G15,"-")>0,"Needs Review","OK") -> OK | L15: =IF(COUNTIF(A$2:A15,A15)>1,"Duplicate","Unique") -> Unique | M15: =IF(OR(K15="Needs Review",L15="Duplicate"),"Review","Ready") -> Ready | N15: =clean_data!D273 & " - " & clean_data!C273 -> Daynile - Traffic Offense
A16: CRM015 | B16: 45992 | C16: Fraud | D16: Yaqshid | E16: Male | F16: Closed | G16: Medium | H16: =IF(B16="","",YEAR(B16)) -> 2025 | I16: =IF(B16="","",MONTH(B16)) -> 12 | J16: =IF(B16="","",TEXT(B16,"mmmm")) -> December | K16: =IF(COUNTBLANK(A16:G16)+COUNTIF(A16:G16,"Unknown")+COUNTIF(A16:G16,"-")>0,"Needs Review","OK") -> OK | L16: =IF(COUNTIF(A$2:A16,A16)>1,"Duplicate","Unique") -> Unique | M16: =IF(OR(K16="Needs Review",L16="Duplicate"),"Review","Ready") -> Ready | N16: =clean_data!D279 & " - " & clean_data!C279 -> Yaqshid - Fraud
A17: CRM00292 | B17: 45912 | C17: Robbery | D17: Wadajir | E17: Male | F17: Closed | G17: =IF(G2="Unknown","High",G2) -> High | H17: =IF(B17="","",YEAR(B17)) -> 2025 | I17: =IF(B17="","",MONTH(B17)) -> 9 | J17: =IF(B17="","",TEXT(B17,"mmmm")) -> September | K17: =IF(COUNTBLANK(A17:G17)+COUNTIF(A17:G17,"Unknown")+COUNTIF(A17:G17,"-")>0,"Needs Review","OK") -> OK | L17: =IF(COUNTIF(A$2:A17,A17)>1,"Duplicate","Unique") -> Unique | M17: =IF(OR(K17="Needs Review",L17="Duplicate"),"Review","Ready") -> Ready | N17: =clean_data!D113 & " - " & clean_data!C113 -> Hodan - Assault
A18: CRM00291 | B18: 46176 | C18: Theft | D18: =IF(D2="Unknown","Hodan",D2) -> Waberi | E18: Male | F18: Under Investigation | G18: Medium | H18: =IF(B18="","",YEAR(B18)) -> 2026 | I18: =IF(B18="","",MONTH(B18)) -> 6 | J18: =IF(B18="","",TEXT(B18,"mmmm")) -> June | K18: =IF(COUNTBLANK(A18:G18)+COUNTIF(A18:G18,"Unknown")+COUNTIF(A18:G18,"-")>0,"Needs Review","OK") -> OK | L18: =IF(COUNTIF(A$2:A18,A18)>1,"Duplicate","Unique") -> Unique | M18: =IF(OR(K18="Needs Review",L18="Duplicate"),"Review","Ready") -> Ready | N18: =clean_data!D48 & " - " & clean_data!C48 -> Yaqshid - Theft
A19: CRM00290 | B19: 45714 | C19: Burglary | D19: =IF(D3="Unknown","Hodan",D3) -> Hodan | E19: Male | F19: Closed | G19: Medium | H19: =IF(B19="","",YEAR(B19)) -> 2025 | I19: =IF(B19="","",MONTH(B19)) -> 2 | J19: =IF(B19="","",TEXT(B19,"mmmm")) -> February | K19: =IF(COUNTBLANK(A19:G19)+COUNTIF(A19:G19,"Unknown")+COUNTIF(A19:G19,"-")>0,"Needs Review","OK") -> OK | L19: =IF(COUNTIF(A$2:A19,A19)>1,"Duplicate","Unique") -> Unique | M19: =IF(OR(K19="Needs Review",L19="Duplicate"),"Review","Ready") -> Ready | N19: =clean_data!D3 & " - " & clean_data!C3 -> Hodan - Robbery
A20: CRM00289 | B20: 46059 | C20: Fraud | D20: Wadajir | E20: Male | F20: {=IF(F2="Unknown",INDEX(F$2:F$292,MODE(MATCH(F$2:F$292,F$2:F$292,0))),F2)} -> Open | G20: Medium | H20: =IF(B20="","",YEAR(B20)) -> 2026 | I20: =IF(B20="","",MONTH(B20)) -> 2 | J20: =IF(B20="","",TEXT(B20,"mmmm")) -> February | K20: =IF(COUNTBLANK(A20:G20)+COUNTIF(A20:G20,"Unknown")+COUNTIF(A20:G20,"-")>0,"Needs Review","OK") -> OK | L20: =IF(COUNTIF(A$2:A20,A20)>1,"Duplicate","Unique") -> Unique | M20: =IF(OR(K20="Needs Review",L20="Duplicate"),"Review","Ready") -> Ready | N20: =clean_data!D115 & " - " & clean_data!C115 -> Karan - Theft
A21: CRM00288 | B21: 45983 | C21: Fraud | D21: Karan | E21: Female | F21: Closed | G21: Medium | H21: =IF(B21="","",YEAR(B21)) -> 2025 | I21: =IF(B21="","",MONTH(B21)) -> 11 | J21: =IF(B21="","",TEXT(B21,"mmmm")) -> November | K21: =IF(COUNTBLANK(A21:G21)+COUNTIF(A21:G21,"Unknown")+COUNTIF(A21:G21,"-")>0,"Needs Review","OK") -> OK | L21: =IF(COUNTIF(A$2:A21,A21)>1,"Duplicate","Unique") -> Unique | M21: =IF(OR(K21="Needs Review",L21="Duplicate"),"Review","Ready") -> Ready | N21: =clean_data!D230 & " - " & clean_data!C230 -> Wadajir - Burglary
A22: CRM00287 | B22: 45736 | C22: Robbery | D22: Daynile | E22: Female | F22: Under Investigation | G22: High | H22: =IF(B22="","",YEAR(B22)) -> 2025 | I22: =IF(B22="","",MONTH(B22)) -> 3 | J22: =IF(B22="","",TEXT(B22,"mmmm")) -> March | K22: =IF(COUNTBLANK(A22:G22)+COUNTIF(A22:G22,"Unknown")+COUNTIF(A22:G22,"-")>0,"Needs Review","OK") -> OK | L22: =IF(COUNTIF(A$2:A22,A22)>1,"Duplicate","Unique") -> Unique | M22: =IF(OR(K22="Needs Review",L22="Duplicate"),"Review","Ready") -> Ready | N22: =clean_data!D218 & " - " & clean_data!C218 -> Karan - Theft
A23: CRM00286 | B23: 45680 | C23: Fraud | D23: Wadajir | E23: unknown | F23: Closed | G23: Medium | H23: =IF(B23="","",YEAR(B23)) -> 2025 | I23: =IF(B23="","",MONTH(B23)) -> 1 | J23: =IF(B23="","",TEXT(B23,"mmmm")) -> January | K23: =IF(COUNTBLANK(A23:G23)+COUNTIF(A23:G23,"Unknown")+COUNTIF(A23:G23,"-")>0,"Needs Review","OK") -> Needs Review | L23: =IF(COUNTIF(A$2:A23,A23)>1,"Duplicate","Unique") -> Unique | M23: =IF(OR(K23="Needs Review",L23="Duplicate"),"Review","Ready") -> Review | N23: =clean_data!D36 & " - " & clean_data!C36 -> Karan - Theft
A24: CRM00285 | B24: 45882 | C24: {=IF(C2="Unknown",INDEX(C$2:C$292,MODE(MATCH(C$2:C$292,C$2:C$292,0))),C2)} -> Assault | D24: Daynile | E24: Unknown | F24: Closed | G24: High | H24: =IF(B24="","",YEAR(B24)) -> 2025 | I24: =IF(B24="","",MONTH(B24)) -> 8 | J24: =IF(B24="","",TEXT(B24,"mmmm")) -> August | K24: =IF(COUNTBLANK(A24:G24)+COUNTIF(A24:G24,"Unknown")+COUNTIF(A24:G24,"-")>0,"Needs Review","OK") -> Needs Review | L24: =IF(COUNTIF(A$2:A24,A24)>1,"Duplicate","Unique") -> Unique | M24: =IF(OR(K24="Needs Review",L24="Duplicate"),"Review","Ready") -> Review | N24: =clean_data!D142 & " - " & clean_data!C142 -> Yaqshid - Theft
A25: CRM00284 | B25: 45933 | C25: Robbery | D25: Yaqshid | E25: unknown | F25: Under Investigation | G25: High | H25: =IF(B25="","",YEAR(B25)) -> 2025 | I25: =IF(B25="","",MONTH(B25)) -> 10 | J25: =IF(B25="","",TEXT(B25,"mmmm")) -> October | K25: =IF(COUNTBLANK(A25:G25)+COUNTIF(A25:G25,"Unknown")+COUNTIF(A25:G25,"-")>0,"Needs Review","OK") -> Needs Review | L25: =IF(COUNTIF(A$2:A25,A25)>1,"Duplicate","Unique") -> Unique | M25: =IF(OR(K25="Needs Review",L25="Duplicate"),"Review","Ready") -> Review | N25: =clean_data!D205 & " - " & clean_data!C205 -> Waberi - Assault
A26: CRM00283 | B26: 45945 | C26: Traffic Offense | D26: Daynile | E26: Male | F26: Closed | G26: Low | H26: =IF(B26="","",YEAR(B26)) -> 2025 | I26: =IF(B26="","",MONTH(B26)) -> 10 | J26: =IF(B26="","",TEXT(B26,"mmmm")) -> October | K26: =IF(COUNTBLANK(A26:G26)+COUNTIF(A26:G26,"Unknown")+COUNTIF(A26:G26,"-")>0,"Needs Review","OK") -> OK | L26: =IF(COUNTIF(A$2:A26,A26)>1,"Duplicate","Unique") -> Unique | M26: =IF(OR(K26="Needs Review",L26="Duplicate"),"Review","Ready") -> Ready | N26: =clean_data!D221 & " - " & clean_data!C221 -> Yaqshid - Theft
A27: CRM00282 | B27: 45825 | C27: Assault | D27: Hodan | E27: Male | F27: Open | G27: High | H27: =IF(B27="","",YEAR(B27)) -> 2025 | I27: =IF(B27="","",MONTH(B27)) -> 6 | J27: =IF(B27="","",TEXT(B27,"mmmm")) -> June | K27: =IF(COUNTBLANK(A27:G27)+COUNTIF(A27:G27,"Unknown")+COUNTIF(A27:G27,"-")>0,"Needs Review","OK") -> OK | L27: =IF(COUNTIF(A$2:A27,A27)>1,"Duplicate","Unique") -> Unique | M27: =IF(OR(K27="Needs Review",L27="Duplicate"),"Review","Ready") -> Ready | N27: =clean_data!D76 & " - " & clean_data!C76 -> Daynile - Assault
A28: CRM00281 | B28: 45915 | C28: Burglary | D28: Yaqshid | E28: Male | F28: Under Investigation | G28: Medium | H28: =IF(B28="","",YEAR(B28)) -> 2025 | I28: =IF(B28="","",MONTH(B28)) -> 9 | J28: =IF(B28="","",TEXT(B28,"mmmm")) -> September | K28: =IF(COUNTBLANK(A28:G28)+COUNTIF(A28:G28,"Unknown")+COUNTIF(A28:G28,"-")>0,"Needs Review","OK") -> OK | L28: =IF(COUNTIF(A$2:A28,A28)>1,"Duplicate","Unique") -> Unique | M28: =IF(OR(K28="Needs Review",L28="Duplicate"),"Review","Ready") -> Ready | N28: =clean_data!D189 & " - " & clean_data!C189 -> Waberi - Assault
A29: CRM00280 | B29: 45844 | C29: Theft | D29: Wadajir | E29: Female | F29: Closed | G29: Medium | H29: =IF(B29="","",YEAR(B29)) -> 2025 | I29: =IF(B29="","",MONTH(B29)) -> 7 | J29: =IF(B29="","",TEXT(B29,"mmmm")) -> July | K29: =IF(COUNTBLANK(A29:G29)+COUNTIF(A29:G29,"Unknown")+COUNTIF(A29:G29,"-")>0,"Needs Review","OK") -> OK | L29: =IF(COUNTIF(A$2:A29,A29)>1,"Duplicate","Unique") -> Unique | M29: =IF(OR(K29="Needs Review",L29="Duplicate"),"Review","Ready") -> Ready | N29: =clean_data!D64 & " - " & clean_data!C64 -> Daynile - Theft
A30: CRM00279 | B30: 46005 | C30: Burglary | D30: Karan | E30: Male | F30: {=IF(F12="Unknown",INDEX(F$2:F$292,MODE(MATCH(F$2:F$292,F$2:F$292,0))),F12)} -> Under Investigation | G30: Medium | H30: =IF(B30="","",YEAR(B30)) -> 2025 | I30: =IF(B30="","",MONTH(B30)) -> 12 | J30: =IF(B30="","",TEXT(B30,"mmmm")) -> December | K30: =IF(COUNTBLANK(A30:G30)+COUNTIF(A30:G30,"Unknown")+COUNTIF(A30:G30,"-")>0,"Needs Review","OK") -> OK | L30: =IF(COUNTIF(A$2:A30,A30)>1,"Duplicate","Unique") -> Unique | M30: =IF(OR(K30="Needs Review",L30="Duplicate"),"Review","Ready") -> Ready | N30: =clean_data!D286 & " - " & clean_data!C286 -> Hodan - Theft
A31: CRM00278 | B31: =IF(B2="Unknown",MEDIAN($B$2:$B$292),B2) -> 46215 | C31: Robbery | D31: Daynile | E31: Male | F31: Closed | G31: High | H31: =IF(B31="","",YEAR(B31)) -> 2026 | I31: =IF(B31="","",MONTH(B31)) -> 7 | J31: =IF(B31="","",TEXT(B31,"mmmm")) -> July | K31: =IF(COUNTBLANK(A31:G31)+COUNTIF(A31:G31,"Unknown")+COUNTIF(A31:G31,"-")>0,"Needs Review","OK") -> OK | L31: =IF(COUNTIF(A$2:A31,A31)>1,"Duplicate","Unique") -> Unique | M31: =IF(OR(K31="Needs Review",L31="Duplicate"),"Review","Ready") -> Ready | N31: =clean_data!D27 & " - " & clean_data!C27 -> Hodan - Assault
A32: CRM00277 | B32: =IF(B2="Unknown",MEDIAN($B$2:$B$292),B2) -> 46215 | C32: Theft | D32: Yaqshid | E32: Male | F32: Closed | G32: Medium | H32: =IF(B32="","",YEAR(B32)) -> 2026 | I32: =IF(B32="","",MONTH(B32)) -> 7 | J32: =IF(B32="","",TEXT(B32,"mmmm")) -> July | K32: =IF(COUNTBLANK(A32:G32)+COUNTIF(A32:G32,"Unknown")+COUNTIF(A32:G32,"-")>0,"Needs Review","OK") -> OK | L32: =IF(COUNTIF(A$2:A32,A32)>1,"Duplicate","Unique") -> Unique | M32: =IF(OR(K32="Needs Review",L32="Duplicate"),"Review","Ready") -> Ready | N32: =clean_data!D283 & " - " & clean_data!C283 -> Waberi - Robbery
A33: CRM00276 | B33: 46037 | C33: Theft | D33: Hodan | E33: Male | F33: Under Investigation | G33: Medium | H33: =IF(B33="","",YEAR(B33)) -> 2026 | I33: =IF(B33="","",MONTH(B33)) -> 1 | J33: =IF(B33="","",TEXT(B33,"mmmm")) -> January | K33: =IF(COUNTBLANK(A33:G33)+COUNTIF(A33:G33,"Unknown")+COUNTIF(A33:G33,"-")>0,"Needs Review","OK") -> OK | L33: =IF(COUNTIF(A$2:A33,A33)>1,"Duplicate","Unique") -> Unique | M33: =IF(OR(K33="Needs Review",L33="Duplicate"),"Review","Ready") -> Ready | N33: =clean_data!D67 & " - " & clean_data!C67 -> Karan - Robbery
A34: CRM00275 | B34: 46162 | C34: Theft | D34: Daynile | E34: Male | F34: Closed | G34: Medium | H34: =IF(B34="","",YEAR(B34)) -> 2026 | I34: =IF(B34="","",MONTH(B34)) -> 5 | J34: =IF(B34="","",TEXT(B34,"mmmm")) -> May | K34: =IF(COUNTBLANK(A34:G34)+COUNTIF(A34:G34,"Unknown")+COUNTIF(A34:G34,"-")>0,"Needs Review","OK") -> OK | L34: =IF(COUNTIF(A$2:A34,A34)>1,"Duplicate","Unique") -> Unique | M34: =IF(OR(K34="Needs Review",L34="Duplicate"),"Review","Ready") -> Ready | N34: =clean_data!D281 & " - " & clean_data!C281 -> Daynile - Theft
A35: CRM00274 | B35: 45877 | C35: Theft | D35: Hodan | E35: Male | F35: Closed | G35: Medium | H35: =IF(B35="","",YEAR(B35)) -> 2025 | I35: =IF(B35="","",MONTH(B35)) -> 8 | J35: =IF(B35="","",TEXT(B35,"mmmm")) -> August | K35: =IF(COUNTBLANK(A35:G35)+COUNTIF(A35:G35,"Unknown")+COUNTIF(A35:G35,"-")>0,"Needs Review","OK") -> OK | L35: =IF(COUNTIF(A$2:A35,A35)>1,"Duplicate","Unique") -> Unique | M35: =IF(OR(K35="Needs Review",L35="Duplicate"),"Review","Ready") -> Ready | N35: =clean_data!D180 & " - " & clean_data!C180 -> Wadajir - Assault
A36: CRM00273 | B36: 45915 | C36: Theft | D36: Karan | E36: Male | F36: Open | G36: Medium | H36: =IF(B36="","",YEAR(B36)) -> 2025 | I36: =IF(B36="","",MONTH(B36)) -> 9 | J36: =IF(B36="","",TEXT(B36,"mmmm")) -> September | K36: =IF(COUNTBLANK(A36:G36)+COUNTIF(A36:G36,"Unknown")+COUNTIF(A36:G36,"-")>0,"Needs Review","OK") -> OK | L36: =IF(COUNTIF(A$2:A36,A36)>1,"Duplicate","Unique") -> Unique | M36: =IF(OR(K36="Needs Review",L36="Duplicate"),"Review","Ready") -> Ready | N36: =clean_data!D131 & " - " & clean_data!C131 -> Karan - Assault
A37: CRM00272 | B37: 46120 | C37: {=IF(C2="Unknown",INDEX(C$2:C$292,MODE(MATCH(C$2:C$292,C$2:C$292,0))),C2)} -> Assault | D37: Hodan | E37: Unknown | F37: Closed | G37: Low | H37: =IF(B37="","",YEAR(B37)) -> 2026 | I37: =IF(B37="","",MONTH(B37)) -> 4 | J37: =IF(B37="","",TEXT(B37,"mmmm")) -> April | K37: =IF(COUNTBLANK(A37:G37)+COUNTIF(A37:G37,"Unknown")+COUNTIF(A37:G37,"-")>0,"Needs Review","OK") -> Needs Review | L37: =IF(COUNTIF(A$2:A37,A37)>1,"Duplicate","Unique") -> Unique | M37: =IF(OR(K37="Needs Review",L37="Duplicate"),"Review","Ready") -> Review | N37: =clean_data!D192 & " - " & clean_data!C192 -> Karan - Theft
A38: CRM00271 | B38: =IF(B2="Unknown",MEDIAN($B$2:$B$292),B2) -> 46215 | C38: Assault | D38: Karan | E38: Male | F38: Closed | G38: High | H38: =IF(B38="","",YEAR(B38)) -> 2026 | I38: =IF(B38="","",MONTH(B38)) -> 7 | J38: =IF(B38="","",TEXT(B38,"mmmm")) -> July | K38: =IF(COUNTBLANK(A38:G38)+COUNTIF(A38:G38,"Unknown")+COUNTIF(A38:G38,"-")>0,"Needs Review","OK") -> OK | L38: =IF(COUNTIF(A$2:A38,A38)>1,"Duplicate","Unique") -> Unique | M38: =IF(OR(K38="Needs Review",L38="Duplicate"),"Review","Ready") -> Ready | N38: =clean_data!D190 & " - " & clean_data!C190 -> Hodan - Assault
A39: CRM00270 | B39: 46058 | C39: Theft | D39: Wadajir | E39: Female | F39: {=IF(F21="Unknown",INDEX(F$2:F$292,MODE(MATCH(F$2:F$292,F$2:F$292,0))),F21)} -> Closed | G39: Medium | H39: =IF(B39="","",YEAR(B39)) -> 2026 | I39: =IF(B39="","",MONTH(B39)) -> 2 | J39: =IF(B39="","",TEXT(B39,"mmmm")) -> February | K39: =IF(COUNTBLANK(A39:G39)+COUNTIF(A39:G39,"Unknown")+COUNTIF(A39:G39,"-")>0,"Needs Review","OK") -> OK | L39: =IF(COUNTIF(A$2:A39,A39)>1,"Duplicate","Unique") -> Unique | M39: =IF(OR(K39="Needs Review",L39="Duplicate"),"Review","Ready") -> Ready | N39: =clean_data!D158 & " - " & clean_data!C158 -> Hodan - Assault
A40: CRM00269 | B40: 45950 | C40: Robbery | D40: Wadajir | E40: Male | F40: Closed | G40: High | H40: =IF(B40="","",YEAR(B40)) -> 2025 | I40: =IF(B40="","",MONTH(B40)) -> 10 | J40: =IF(B40="","",TEXT(B40,"mmmm")) -> October | K40: =IF(COUNTBLANK(A40:G40)+COUNTIF(A40:G40,"Unknown")+COUNTIF(A40:G40,"-")>0,"Needs Review","OK") -> OK | L40: =IF(COUNTIF(A$2:A40,A40)>1,"Duplicate","Unique") -> Unique | M40: =IF(OR(K40="Needs Review",L40="Duplicate"),"Review","Ready") -> Ready | N40: =clean_data!D196 & " - " & clean_data!C196 -> Waberi - Theft
...

Sheet Finding
A1: Key Findings
A5: Hodan has the highest number of reported crimes – 84 incidents.
A6: Theft is the most common crime type – 84 incidents.
A7: High-severity incidents represent a significant share of cases – 106 incidents.
A8: Closed cases make up a substantial portion of reported cases – 123 cases.
A9: Many cases remain active or under investigation – 144 cases.
A10: Some cases are referred to other authorities/departments – 25 cases.
A11: The raw dataset contained missing/unknown values – 142 across 8 variables.
A15: Strategic Recommendations
A17: 1. Increase police resources in Hodan and Wadajir.
A18: 2. Create a case-clearance team to focus on open and investigation cases.
A19: 3. Strengthen theft prevention through public awareness and surveillance.
... A21: 5. Improve coordination between police and other relevant authorities.

Sheet Dashboard
B6: TOTAL INCIDENTS | G6: CLOSED CAES | K6: HIGH SEVERITY INCIDENTS | O6: OPEN / UNDER INVESTIGATION
D7: =COUNTA(clean_data!A2:A293) -> 292 | H7: =COUNTIF(clean_data!F2:F293, "Closed") -> 123 | L7: =COUNTIF(clean_data!G2:G293, "High") -> 106 | P7: =COUNTIF(clean_data!F2:F293,"Open")+COUNTIF(clean_data!F2:F293,"Under Investigation") -> 144
B10: Crimes by District | O10: KISASKA NOCYADODA
A12: Row Labels | B12: Count of Crime_ID | N12: Row Labels | O12: Count of Case_Status
A13: Hodan | B13: 25 | N13: Closed | O13: 123
A14: Wadajir | B14: 10 | N14: Open | O14: 68
A15: Daynile | B15: 9 | N15: Referred | O15: 25
A16: Karan | B16: 6 | N16: Under Investigation | O16: 77
A17: Yaqshid | B17: 5 | N17: Grand Total | O17: 293
A18: Waberi | B18: 5
A19: Grand Total | B19: 60
B37: serevity level
O40: DANBIGA UGU BDAN EE DHACA
A43: Row Labels | B43: Count of Severity_Level | N43: Row Labels | O43: Count of Crime_Type
A44: High | B44: 107 | N44: Assault | O44: 60
A45: Low | B45: 30 | N45: Burglary | O45: 18
A46: Medium | B46: 156 | N46: Fraud | O46: 57
A47: Grand Total | B47: 293 | N47: Robbery | O47: 44
N48: Theft | O48: 85
N49: Traffic Offense | O49: 29
N50: Grand Total | O50: 293
B62: BILAHA IO DANBIYADA DHACAEYN | P62: Year with the Most Crimes
N65: Count of Crime_ID | O65: Column Labels
A66: Row Labels | B66: Count of Crime_month name | N66: Row Labels | O66: Assault | P66: Burglary | Q66: Fraud | R66: Robbery | S66: Theft | T66: Traffic Offense | U66: Grand Total
A67: January | B67: 27 | N67: 2025 | O67: 33 | P67: 15 | Q67: 33 | R67: 25 | S67: 46 | T67: 17 | U67: 169
A68: February | B68: 34 | N68: Grand Total | O68: 33 | P68: 15 | Q68: 33 | R68: 25 | S68: 46 | T68: 17 | U68: 169
A69: March | B69: 21
A70: April | B70: 28
A71: May | B71: 30
A72: July | B72: 56
A73: August | B73: 16
A74: September | B74: 17
A75: October | B75: 13
A76: November | B76: 13
A77: December | B77: 13
B78: 1
A79: Grand Total | B79: 269
B87: GENDERKA IO DHIMATADA NOCYADA KU DHACO | V87: Gender and Crime Type Analysis
A89: Count of Victim_Gender | B89: Column Labels | V89: District | W89: (All)
A90: Row Labels | B90: Assault | C90: Burglary | D90: Fraud | E90: Robbery | F90: Theft | G90: Traffic Offense | H90: Grand Total
...

Sheet Sheet1
A1: Crime_ID | B1: Crime_Date | C1: Crime_Type | D1: District | E1: Victim_Gender | F1: Case_Status | G1: Severity_Level | L1: missing raws of each column
A2: CRM00054 | B2: 45849 | C2: Theft | D2: Karan | E2: Male | F2: Closed | L2: ID | M2: =COUNTBLANK(A2:A293)+COUNTIF(A2:A293,"Unknown")+COUNTIF(A2:A293,"N/A")+COUNTIF(A2:A293,"NULL") -> 15
A3: CRM00290 | B3: 45714 | C3: Burglary | E3: Male | F3: Closed | G3: Medium | L3: Crime_Date | M3: =COUNTBLANK(B2:B293)+COUNTIF(B2:B293,"Unknown")+COUNTIF(B2:B293,"N/A")+COUNTIF(B2:B293,"NULL") -> 17
A4: CRM00143 | B4: 46168 | C4: Theft | D4: Wadajir | E4: Female | G4: Medium | L4: Crime_Type | M4: =COUNTBLANK(C2:C293)+COUNTIF(C2:C293,"Unknown")+COUNTIF(C2:C293,"N/A")+COUNTIF(C2:C293,"NULL") -> 15
A5: CRM00198 | B5: 45705 | C5: Assault | D5: Wadajir | E5: Male | F5: Open | G5: High | L5: District | M5: =COUNTBLANK(D2:D293)+COUNTIF(D2:D293,"Unknown")+COUNTIF(D2:D293,"N/A")+COUNTIF(D2:D293,"NULL") -> 16
A6: CRM00244 | B6: 46080 | C6: Assault | D6: Hodan | E6: Female | F6: Under Investigation | G6: High | L6: Gender | M6: =COUNTBLANK(E2:E293)+COUNTIF(E2:E293,"Unknown")+COUNTIF(E2:E293,"N/A")+COUNTIF(E2:E293,"NULL") -> 45
A7: CRM00265 | B7: 45705 | C7: Fraud | D7: Wadajir | E7: Male | F7: Under Investigation | G7: Medium | L7: Case_Status | M7: =COUNTBLANK(F2:F293)+COUNTIF(F2:F293,"Unknown")+COUNTIF(F2:F293,"N/A")+COUNTIF(F2:F293,"NULL") -> 16
A8: CRM00138 | B8: 46098 | C8: Theft | D8: Yaqshid | E8: Female | F8: Under Investigation | G8: Medium | L8: Severity_Level | M8: =COUNTBLANK(G2:G293)+COUNTIF(G2:G293,"Unknown")+COUNTIF(G2:G293,"N/A")+COUNTIF(G2:G293,"NULL") -> 18
A9: CRM00028 | B9: 45702 | C9: Fraud | D9: Yaqshid | E9: Male | G9: Medium | L9: total missing raws | M9: =SUM(M2:M8) -> 142
A10: CRM00018 | B10: 45816 | C10: Robbery | D10: Yaqshid | E10: Male | F10: Under Investigation | G10: High
A11: CRM00096 | B11: 45755 | C11: Fraud | D11: Daynile | E11: Male | F11: Under Investigation | G11: Medium
A12: CRM00153 | B12: 46118 | C12: Theft | D12: Hodan | E12: Unknown | F12: Under Investigation | G12: Medium
B13: 46215 | C13: Assault | D13: Waberi | E13: Male | F13: Open | G13: High
A14: CRM00122 | B14: 46003 | C14: Theft | D14: Hodan | E14: Female | F14: Under Investigation | G14: Medium
A15: CRM00245 | B15: 46178 | C15: Theft | D15: Daynile | E15: Male | F15: Open | G15: Medium
A16: CRM00035 | B16: 45817 | C16: Traffic Offense | D16: Karan | E16: Male | F16: Under Investigation | G16: Low
A17: CRM00210 | B17: 45755 | D17: Daynile | E17: Female | F17: Closed | G17: High
A18: CRM00073 | B18: 45974 | C18: Traffic Offense | D18: Yaqshid | E18: Female | F18: Under Investigation | G18: Low
A19: CRM00262 | B19: 46042 | C19: Assault | D19: Wadajir | E19: Female | F19: Closed
A20: CRM00235 | B20: 45712 | C20: Theft | E20: Male | F20: Referred | G20: Medium | M20: =_xleta.SUM -> #VALUE!
A21: CRM00158 | B21: 45919 | C21: Assault | D21: Wadajir | E21: Male | F21: Under Investigation | G21: High
A22: CRM00251 | B22: 46068 | C22: Robbery | D22: Hodan | E22: Female | F22: Closed | G22: High
A23: CRM00213 | B23: - | C23: Assault | D23: Wadajir | E23: Male | F23: Open | G23: High
A24: CRM00026 | B24: 45782 | C24: Theft | D24: Hodan | E24: Male | G24: Medium
A25: CRM00216 | B25: 46167 | D25: Karan | E25: Male | F25: Closed | G25: High
A26: CRM00064 | B26: 45885 | D26: Karan | E26: Male | F26: Open | G26: Medium
A27: CRM00278 | B27: N/A | C27: Robbery | D27: Daynile | E27: Male | F27: Closed | G27: High
A28: CRM00021 | B28: 45971 | C28: Traffic Offense | D28: Daynile | E28: Male | F28: Closed | G28: Low
A29: CRM00045 | B29: 45922 | C29: Robbery | D29: Hodan | E29: Male | F29: Closed | G29: High
A30: CRM00252 | B30: 46136 | C30: Assault | D30: Hodan | E30: Unknown | F30: Closed | G30: High
A31: CRM00234 | C31: Traffic Offense | D31: Daynile | E31: Unknown | F31: Closed | G31: Low
A32: CRM00049 | B32: 46208 | C32: Burglary | D32: Yaqshid | E32: Unknown | F32: Under Investigation | G32: Medium
A33: CRM00178 | B33: 46182 | C33: Theft | D33: Daynile | E33: NULL | F33: Under Investigation | G33: Medium
A34: CRM00140 | B34: 45671 | C34: Robbery | D34: Wadajir | E34: Female | F34: Under Investigation | G34: High
A35: CRM00215 | B35: 45853 | C35: Fraud | D35: Daynile | E35: Female | F35: Under Investigation | G35: Medium
A36: CRM00286 | B36: 45680 | C36: Fraud | D36: Wadajir | F36: Closed | G36: Medium
A37: CRM00240 | B37: 45761 | C37: Traffic Offense | D37: Waberi | E37: Male | F37: Open | G37: Low
B38: 45822 | C38: Robbery | D38: Hodan | E38: Unknown | F38: Closed | G38: High
A39: CRM00161 | B39: 45957 | C39: Theft | D39: Karan | E39: Male | F39: Under Investigation
A40: CRM00254 | B40: N/A | D40: Karan | E40: Male | F40: Open | G40: High
...

Sheet analysing data
A1: ANALYSIS SHEET — Formulas, Cleaning References & Calculations | M1: Crime_ID | N1: Crime_Date | O1: Crime_Type | P1: District | Q1: Victim_Gender | R1: Case_Status | S1: Severity_Level
M2: CRM001 | N2: 46215 | O2: Assault | P2: Waberi | Q2: Male | R2: Open | S2: High
A3: Missing-Value Fill Reference (Part B — Data Cleaning) | M3: CRM002 | N3: 45822 | O3: Robbery | P3: Hodan | Q3: Unknown | R3: Closed | S3: High | V3: Count
A4: Field | B4: Fill Value Used | C4: Method | M4: CRM003 | N4: 46017 | O4: Robbery | P4: Daynile | Q4: Male | R4: Open | S4: High | U4: Theft | V4: =COUNTIF($O$2:$O$293,U4) -> 84
A5: Crime_Type | B5: =INDEX($U$4:$U$9,MATCH(MAX($V$4:$V$9),$V$4:$V$9,0)) -> Theft | C5: Mode (most frequent category) | M5: CRM004 | N5: 45832 | O5: Assault | P5: Yaqshid | Q5: Female | R5: Referred | S5: High | U5: Burglary | V5: =COUNTIF($O$2:$O$293,U5) -> 18
A6: District | B6: =INDEX($U$12:$U$17,MATCH(MAX($V$12:$V$17),$V$12:$V$17,0)) -> Hodan | C6: Mode (most frequent category) | M6: CRM005 | N6: 46045 | O6: Assault | P6: Daynile | Q6: Male | R6: Under Investigation | S6: High | U6: Assault | V6: =COUNTIF($O$2:$O$293,U6) -> 60
A7: Victim_Gender | B7: =INDEX($U$20:$U$22,MATCH(MAX($V$20:$V$22),$V$20:$V$22,0)) -> Male | C7: Mode (most frequent category) | M7: CRM006 | N7: 46039 | O7: Robbery | P7: Daynile | Q7: Male | R7: Closed | S7: High | U7: Fraud | V7: =COUNTIF($O$2:$O$293,U7) -> 57
A8: Case_Status | B8: =INDEX($U$25:$U$28,MATCH(MAX($V$25:$V$28),$V$25:$V$28,0)) -> Closed | C8: Mode (most frequent category) | M8: CRM007 | N8: 46159 | O8: Traffic Offense | P8: Wadajir | Q8: Male | R8: Under Investigation | S8: Medium | U8: Robbery | V8: =COUNTIF($O$2:$O$293,U8) -> 44
A9: Severity_Level | B9: =INDEX($U$31:$U$33,MATCH(MAX($V$31:$V$33),$V$31:$V$33,0)) -> Medium | C9: Mode (most frequent category) | M9: CRM008 | N9: 45850 | O9: Traffic Offense | P9: Daynile | Q9: Female | R9: Closed | S9: Low | U9: Traffic Offense | V9: =COUNTIF($O$2:$O$293,U9) -> 29
A10: Crime_Date | B10: =MEDIAN(N2:N286) -> 45974 | C10: Median (robust to skew/outliers vs. mean) | M10: CRM009 | N10: 46204 | O10: Theft | P10: Wadajir | Q10: Male | R10: Open | S10: Medium | V10: =SUM(V4:V9) -> 292
M11: CRM010 | N11: 46063 | O11: Robbery | P11: Daynile | Q11: Female | R11: Under Investigation | S11: High | U11: District
M12: CRM011 | N12: 45748 | O12: Burglary | P12: Waberi | Q12: Female | R12: Under Investigation | S12: Medium | U12: Karan | V12: =COUNTIF($P$2:$P$293,U12) -> 32
M13: CRM012 | N13: 46161 | O13: Traffic Offense | P13: Hodan | Q13: Female | R13: Open | S13: Low | U13: Wadajir | V13: =COUNTIF($P$2:$P$293,U13) -> 62
M14: CRM013 | N14: 46050 | O14: Theft | P14: Wadajir | Q14: Male | R14: Closed | S14: Medium | U14: Hodan | V14: =COUNTIF($P$2:$P$293,U14) -> 84
M15: CRM014 | N15: 45951 | O15: Fraud | P15: Karan | Q15: Male | R15: Open | S15: Medium | U15: Yaqshid | V15: =COUNTIF($P$2:$P$293,U15) -> 44
M16: CRM015 | N16: 45992 | O16: Fraud | P16: Yaqshid | Q16: Male | R16: Closed | S16: Medium | U16: Daynile | V16: =COUNTIF($P$2:$P$293,U16) -> 38
M17: CRM00292 | N17: 45912 | O17: Robbery | P17: Wadajir | Q17: Male | R17: Closed | S17: =IF(S2="Unknown","High",S2) -> High | U17: Waberi | V17: =COUNTIF($P$2:$P$293,U17) -> 32
M18: CRM00291 | N18: 46176 | O18: Theft | P18: =IF(P2="Unknown","Hodan",P2) -> Waberi | Q18: Male | R18: Under Investigation | S18: Medium | V18: =SUM(V12:V17) -> 292
M19: CRM00290 | N19: 45714 | O19: Burglary | P19: =IF(P3="Unknown","Hodan",P3) -> Hodan | Q19: Male | R19: Closed | S19: Medium | U19: Victim_Gender
M20: CRM00289 | N20: 46059 | O20: Fraud | P20: Wadajir | Q20: Male | R20: {=IF(R2="Unknown",INDEX(R$2:R$292,MODE(MATCH(R$2:R$292,R$2:R$292,0))),R2)} -> Open | S20: Medium | U20: Male | V20: =COUNTIF($Q$2:$Q$293,U20) -> 160
M21: CRM00288 | N21: 45983 | O21: Fraud | P21: Karan | Q21: Female | R21: Closed | S21: Medium | U21: Female | V21: =COUNTIF($Q$2:$Q$293,U21) -> 89
M22: CRM00287 | N22: 45736 | O22: Robbery | P22: Daynile | Q22: Female | R22: Under Investigation | S22: High | U22: Unknown | V22: =COUNTIF($Q$2:$Q$293,U22) -> 43
M23: CRM00286 | N23: 45680 | O23: Fraud | P23: Wadajir | Q23: unknown | R23: Closed | S23: Medium
M24: CRM00285 | N24: 45882 | O24: {=IF(O2="Unknown",INDEX(O$2:O$292,MODE(MATCH(O$2:O$292,O$2:O$292,0))),O2)} -> Assault | P24: Daynile | Q24: Unknown | R24: Closed | S24: High | U24: Case_Status
M25: CRM00284 | N25: 45933 | O25: Robbery | P25: Yaqshid | Q25: unknown | R25: Under Investigation | S25: High | U25: Open | V25: =COUNTIF($R$2:$R$293,U25) -> 67
M26: CRM00283 | N26: 45945 | O26: Traffic Offense | P26: Daynile | Q26: Male | R26: Closed | S26: Low | U26: Closed | V26: =COUNTIF($R$2:$R$293,U26) -> 123
M27: CRM00282 | N27: 45825 | O27: Assault | P27: Hodan | Q27: Male | R27: Open | S27: High | U27: Under Investigation | V27: =COUNTIF($R$2:$R$293,U27) -> 77
M28: CRM00281 | N28: 45915 | O28: Burglary | P28: Yaqshid | Q28: Male | R28: Under Investigation | S28: Medium | U28: Referred | V28: =COUNTIF($R$2:$R$293,U28) -> 25
M29: CRM00280 | N29: 45844 | O29: Theft | P29: Wadajir | Q29: Female | R29: Closed | S29: Medium | V29: =SUM(V25:V28) -> 292
M30: CRM00279 | N30: 46005 | O30: Burglary | P30: Karan | Q30: Male | R30: {=IF(R12="Unknown",INDEX(R$2:R$292,MODE(MATCH(R$2:R$292,R$2:R$292,0))),R12)} -> Under Investigation | S30: Medium | U30: Severity_Level
M31: CRM00278 | N31: =IF(N2="Unknown",MEDIAN($B$2:$B$292),N2) -> 46215 | O31: Robbery | P31: Daynile | Q31: Male | R31: Closed | S31: High | U31: Low | V31: =COUNTIF($S$2:$S$293,U31) -> 30
M32: CRM00277 | N32: =IF(N2="Unknown",MEDIAN($B$2:$B$292),N2) -> 46215 | O32: Theft | P32: Yaqshid | Q32: Male | R32: Closed | S32: Medium | U32: Medium | V32: =COUNTIF($S$2:$S$293,U32) -> 156
M33: CRM00276 | N33: 46037 | O33: Theft | P33: Hodan | Q33: Male | R33: Under Investigation | S33: Medium | U33: High | V33: =COUNTIF($S$2:$S$293,U33) -> 106
M34: CRM00275 | N34: 46162 | O34: Theft | P34: Daynile | Q34: Male | R34: Closed | S34: Medium
M35: CRM00274 | N35: 45877 | O35: Theft | P35: Hodan | Q35: Male | R35: Closed | S35: Medium
M36: CRM00273 | N36: 45915 | O36: Theft | P36: Karan | Q36: Male | R36: Open | S36: Medium
M37: CRM00272 | N37: 46120 | O37: {=IF(O2="Unknown",INDEX(O$2:O$292,MODE(MATCH(O$2:O$292,O$2:O$292,0))),O2)} -> Assault | P37: Hodan | Q37: Unknown | R37: Closed | S37: Low
M38: CRM00271 | N38: =IF(N2="Unknown",MEDIAN($B$2:$B$292),N2) -> 46215 | O38: Assault | P38: Karan | Q38: Male | R38: Closed | S38: High
M39: CRM00270 | N39: 46058 | O39: Theft | P39: Wadajir | Q39: Female | R39: {=IF(R21="Unknown",INDEX(R$2:R$292,MODE(MATCH(R$2:R$292,R$2:R$292,0))),R21)} -> Closed | S39: Medium
M40: CRM00269 | N40: 45950 | O40: Robbery | P40: Wadajir | Q40: Male | R40: Closed | S40: High
...
